Workbook
Name F_esp_GN1270: '[1]EVOLUÇÃO FATURAMENTO'!$K$20
Name F_esp_GN1400: '[1]EVOLUÇÃO FATURAMENTO'!$K$13
Name F_esp_GN1410: '[1]EVOLUÇÃO FATURAMENTO'!$K$51
Name F_esp_GN1420: '[1]EVOLUÇÃO FATURAMENTO'!$K$30
Name F_esp_GN1421: '[1]EVOLUÇÃO FATURAMENTO'!$K$40
Name K_trab_GN1270: FATURAMENTO_COMPILADO!$N$7
Name K_trab_GN1400: FATURAMENTO_COMPILADO!$N$6
Name K_trab_GN1410: FATURAMENTO_COMPILADO!$N$10
Name K_trab_GN1420: FATURAMENTO_COMPILADO!$N$8
Name K_trab_GN1421: FATURAMENTO_COMPILADO!$N$9
Name L_uteis_GN1270: FATURAMENTO_COMPILADO!$M$7
Name L_uteis_GN1400: FATURAMENTO_COMPILADO!$M$6
Name L_uteis_GN1410: FATURAMENTO_COMPILADO!$M$10
Name L_uteis_GN1420: FATURAMENTO_COMPILADO!$M$8
Name L_uteis_GN1421: FATURAMENTO_COMPILADO!$M$9
Name M_rest_GN1270: FATURAMENTO_COMPILADO!$O$7
Name M_rest_GN1400: FATURAMENTO_COMPILADO!$O$6
Name M_rest_GN1410: FATURAMENTO_COMPILADO!$O$10
Name M_rest_GN1420: FATURAMENTO_COMPILADO!$O$8
Name M_rest_GN1421: FATURAMENTO_COMPILADO!$O$9
Name SegmentaçãodeDados_Competência: #N/A
Name SegmentaçãodeDados_CR: #N/A

Sheet FATURAMENTO_COMPILADO
A2: COMPETÊNCIA 07/2026 · Atualizado em 26/06/2026
F4: COLUNA MANUAL | L4: Agosto-26 | M4: COLUNAS PREENCHIDAS MANUAIS
A5: GN | B5: RESPONSÁVEL | C5: CONTRATO | D5: FAT. TOTAL (R$) | E5: PROJEÇÃO (R$) | F5: META (R$) | G5: % REAL. | H5: VALOR REST. (R$) | I5: MÉDIA DIÁRIA (R$) | J5: % RITMO | K5: META AJUST. DIÁRIA (R$) | L5: FAT. ESPERADO (R$) | M5: Dias Úteis | N5: Dias Trabalhados | O5: Dias Restantes | S5: GN_p | U5: Indicador | V5: Valor | W5: Esperado(linha)
A6: GN1270 | B6: CESAR LEITÃO | C6: LACAN | D6: =SUMIFS('REND-Boletim de Produção'!AI$6:AI$3282,'REND-Boletim de Produção'!AG$6:AG$3282,FATURAMENTO_COMPILADO!$L$4,'REND-Boletim de Produção'!D$6:D$3282,A6) -> 368747.36 | E6: =(D6/N6)*M6 -> 838062.18 | F6: 560405.75 | G6: =IFERROR(D6/F6,"") -> 0.65800067 | H6: =F6-D6 -> 191658.39 | I6: =D6/K_trab_GN1270 -> 29405.69 | J6: =IFERROR(E6/F6,"") -> 1.4954561 | K6: =F6/M_rest_GN1400 -> 40028.982 | L6: =(F6/M6)*N6 -> 246578.53 | M6: 25 | N6: 11 | O6: =M6-N6 -> 14 | S6: GN1400 | U6: Faturamento Total | V6: =D12 -> 3489463.8 | W6: =$V$9 -> 393462.72
A7: GN1400 | B7: CESAR LEITÃO | C7: ARAUCO - SILVICULTURA | D7: =SUMIFS('REND-Boletim de Produção'!AI$6:AI$3282,'REND-Boletim de Produção'!AG$6:AG$3282,FATURAMENTO_COMPILADO!$L$4,'REND-Boletim de Produção'!D$6:D$3282,A7) -> 1604375.7 | E7: =(D7/N7)*M7 -> 3267604 | F7: 3191156.5 | G7: =IFERROR(D7/F7,"") -> 0.50275681 | H7: =F7-D7 -> 1586780.9 | I7: =D7/K_trab_GN1400 -> 145852.33 | J7: =IFERROR(E7/F7,"") -> 1.023956 | K7: =F7/M_rest_GN1400 -> 227939.75 | L7: =(F7/M7)*N7 -> 1566840.4 | M7: 25.54 | N7: 12.54 | O7: =M7-N7 -> 13 | S7: GN1270 | U7: Projeção | V7: =E12 -> 7192843.9 | W7: =$V$9 -> 393462.72
A8: GN1420 | B8: CESAR LEITÃO | C8: INNOVATECH - SILVICULTURA | D8: =SUMIFS('REND-Boletim de Produção'!AI$6:AI$3282,'REND-Boletim de Produção'!AG$6:AG$3282,FATURAMENTO_COMPILADO!$L$4,'REND-Boletim de Produção'!D$6:D$3282,FATURAMENTO_COMPILADO!A8) -> 0 | E8: =(D8/N8)*M8 -> 0 | F8: 0 | G8: =IFERROR(D8/F8,"") | H8: =F8-D8 -> 0 | I8: =D8/K_trab_GN1420 -> 0 | J8: =IFERROR(E8/F8,"") | K8: =F8/M_rest_GN1400 -> 0 | L8: =(F8/M8)*N8 -> 0 | M8: 23 | N8: 12 | O8: =M8-N8 -> 11 | S8: GN1420 | U8: Meta | V8: =F12 -> 9919195.1 | W8: =$V$9 -> 393462.72
A9: GN1421 | B9: DEIVIT BORGES | C9: INNOVATECH - SILVICULTURA (COLPAR) | D9: =SUMIFS('REND-Boletim de Produção'!AI$6:AI$29631,'REND-Boletim de Produção'!AG$6:AG$29631,FATURAMENTO_COMPILADO!$L$4,'REND-Boletim de Produção'!D$6:D$29631,FATURAMENTO_COMPILADO!A9) -> 576186.01 | E9: =(D9/N9)*M9 -> 1204050.1 | F9: 2247913.8 | G9: =IFERROR(D9/F9,"") -> 0.25632033 | H9: =F9-D9 -> 1671727.8 | I9: =D9/K_trab_GN1421 -> 48297.234 | J9: =IFERROR(E9/F9,"") -> 0.53563 | K9: =F9/M_rest_GN1400 -> 160565.27 | L9: =(F9/M9)*N9 -> 1075716.5 | M9: 24.93 | N9: 11.93 | O9: =M9-N9 -> 13 | S9: GN1421 | U9: Fat Esperado | V9: =F12/AVERAGE(M6:M11) -> 393462.72
A10: GN1410 | B10: SÉLIO AGUIAR | C10: BRACELL MS - SILVICULTURA | D10: =SUMIFS('REND-Boletim de Produção'!AI$6:AI$3282,'REND-Boletim de Produção'!AG$6:AG$3282,FATURAMENTO_COMPILADO!$L$4,'REND-Boletim de Produção'!D$6:D$3282,FATURAMENTO_COMPILADO!A10)-10956.35 -> 752926.62 | E10: =(D10/N10)*M10 -> 1523032.5 | F10: 2889742 | G10: =IFERROR(D10/F10,"") -> 0.2605515 | H10: =F10-D10 -> 2136815.4 | I10: =D10/K_trab_GN1410 -> 59238.916 | J10: =IFERROR(E10/F10,"") -> 0.52704792 | K10: =F10/M_rest_GN1400 -> 206410.15 | L10: =(F10/M10)*N10 -> 1428573.4 | M10: 25.71 | N10: 12.71 | O10: =M10-N10 -> 13 | S10: GN1410
A11: GN1430 | B11: SÉLIO AGUIAR | C11: Eucatex - Silvicultura | D11: =164864.15+22364.036 -> 187228.19 | E11: =(D11/N11)*M11 -> 360095.12 | F11: 1029977 | G11: =IFERROR(D11/F11,"") -> 0.18177899 | H11: =F11-D11 -> 842748.84 | I11: =D11/K_trab_GN1410 -> 14730.778 | J11: =IFERROR(E11/F11,"") -> 0.34961471 | K11: =F11/M_rest_GN1400 -> 73569.788 | L11: =(F11/M11)*N11 -> 535527.2 | M11: 27.08 | N11: 14.08 | O11: =M11-N11 -> 13
A12: TOTAL GERAL | D12: =SUM(D6:D11) -> 3489463.8 | E12: =SUM(E6:E11) -> 7192843.9 | F12: =SUM(F6:F11) -> 9919195.1 | G12: =D12/F12 -> 0.35178901 | H12: =F12-D12 -> 6429731.3

Sheet REND-Boletim de Produção
A1: =AI4 -> 71422.811 | C1: Boletim de Produção CDO | AD1: Emitido Por: Cilas Andrei da Silva Serrado
T4: =SUBTOTAL(9,T6:T3282) -> 212.45 | Z4: =SUBTOTAL(9,Z6:Z3282) -> 5654.16 | AI4: =SUBTOTAL(9,AI6:AI3282) -> 71422.811 | AP4: =SUBTOTAL(9,AP6:AP3282) -> -29751.423 | AS4: =AI4 -> 71422.811
A5: CDO | B5: Data | C5: Competencia | D5: CR | E5: Contrato | F5: Funcao | G5: Escala de Horas | H5: Mat. Supervisor | I5: Supervisor | J5: Mat. Encarregado | K5: Encarregado | L5: Turma | M5: Cod. Operacao | N5: Operacao | O5: Und. Medida | P5: Cod. Projeto | Q5: Projeto | R5: Talhao | S5: Hora Trabalhada | T5: Producao | U5: Hora Improdutiva | V5: Total Horas | W5: Rendimento Previsto | X5: Rendimento Efetivo | Y5: Rendimento Total | Z5: Preço do Recurso | AA5: Status | AB5: Tipo Recurso | AC5: Criado por | AD5: Alterado por | AE5: Data Registro | AF5: Observacao | AG5: Competência | AH5: Preço | AI5: Valor Total | AJ5: Agrupamentos de Atividades | AK5: OPERAÇÃO + CR + COD | AL5: Duplicidade | AM5: Produção Prevista ((hora trab+horas improdutivas)/ rend previsto) | AN5: fatu previsto (prod prevista x preço do recurso) | AO5: Faturamento Realizado | AP5: Resultado Negociado
A6: 46435 | B6: 46194 | C6: 1°- 07/2026 | D6: GN1400 | E6: Arauco - Silvicultura | F6: Trabalhador Florestal | G6: 8 | H6: 10859 | I6: RENATO DE SOUZA PEREIRA | J6: 10093 | K6: JONATHAN FONSECA DE OLIVEIRA | L6: JONATHAN FONSECA DE OLIVEIRA | M6: REF12 | N6: PLANTIO MANUAL 1.110 plantas/HA, mudas com tratamento (MAP e Cupinicida), mudas SEM TUBETE + Replantio | O6: HA | P6: 400 | Q6: Rosa Maria | R6: 364 | S6: 24 | T6: 29.17 | U6: 0 | V6: 24 | W6: 12.32 | X6: 0.82 | Y6: 0.82 | Z6: 1237.4 | AA6: CONCLUIDO | AB6: Principal | AC6: Jonathan Fonseca de Oliveira | AD6: Lucas Barbosa Ramos | AE6: 46194.843 | AF6: máquinas 282 trabalhou 8 horas | AG6: =IF(B6=0,"",PROPER(TEXT(IF(DAY(B6)>20,EDATE(B6,1),B6),"MMMM-aa"))) -> Julho-26 | AH6: =_xlfn.XLOOKUP(AK6,'Base de Preços'!P$7:P$3001,'Base de Preços'!J$7:J$3001,"",0) -> 1627.29 | AI6: =IF(AB6="Principal",AH6*T6,0) -> 47468.049 | AJ6: =_xlfn.XLOOKUP(N6,Agrupamentos!C$3:C$496,Agrupamentos!D$3:D$496,"",0) -> PLANTIO | AK6: =N6&D6&M6 -> PLANTIO MANUAL 1.110 plantas/HA, mudas com tratamento (MAP e Cupinicida), mudas SEM TUBETE + ReplantioGN1400REF12 | AL6: =CONCATENATE(A6,D6,F6,K6,N6,Q6,R6,AB6,T6,AG6,U6,V6,AE6,B6) -> 46435GN1400Trabalhador FlorestalJONATHAN FONSECA DE OLIVEIRAPLANTIO MANUAL 1.110 plantas/HA, mudas com tratamento (MAP e Cupinicida), mudas SEM TUBETE + ReplantioRosa Maria364Principal29,17Julho-2602446194,843148148146194 | AM6: =IFERROR(V6/W6,"") -> 1.9480519 | AN6: =IFERROR(AM6*Z6,"") -> 2410.5195 | AO6: =Z6*T6 -> 36094.958 | AP6: =IFERROR(AO6-AN6,"") -> 33684.439
A7: 46435 | B7: 46194 | C7: 1°- 07/2026 | D7: GN1400 | E7: Arauco - Silvicultura | F7: Trabalhador Florestal | G7: 8 | H7: 10859 | I7: RENATO DE SOUZA PEREIRA | J7: 10093 | K7: JONATHAN FONSECA DE OLIVEIRA | L7: JONATHAN FONSECA DE OLIVEIRA | M7: REF12 | N7: PLANTIO MANUAL 1.110 plantas/HA, mudas com tratamento (MAP e Cupinicida), mudas SEM TUBETE + Replantio | O7: HA | P7: 400 | Q7: Rosa Maria | R7: 363 | S7: 8 | T7: 16 | U7: 0 | V7: 8 | W7: 12.32 | X7: 0.5 | Y7: 0.5 | Z7: 1237.4 | AA7: EM ANDAMENTO | AB7: Principal | AC7: Jonathan Fonseca de Oliveira | AD7: Lucas Barbosa Ramos | AE7: 46195.68 | AF7: máquinas 282 trabalhou 8 horas | AG7: =IF(B7=0,"",PROPER(TEXT(IF(DAY(B7)>20,EDATE(B7,1),B7),"MMMM-aa"))) -> Julho-26 | AH7: =_xlfn.XLOOKUP(AK7,'Base de Preços'!P$7:P$3001,'Base de Preços'!J$7:J$3001,"",0) -> 1627.29 | AI7: =IF(AB7="Principal",AH7*T7,0) -> 26036.64 | AJ7: =_xlfn.XLOOKUP(N7,Agrupamentos!C$3:C$496,Agrupamentos!D$3:D$496,"",0) -> PLANTIO | AK7: =N7&D7&M7 -> PLANTIO MANUAL 1.110 plantas/HA, mudas com tratamento (MAP e Cupinicida), mudas SEM TUBETE + ReplantioGN1400REF12 | AL7: =CONCATENATE(A7,D7,F7,K7,N7,Q7,R7,AB7,T7,AG7,U7,V7,AE7,B7) -> 46435GN1400Trabalhador FlorestalJONATHAN FONSECA DE OLIVEIRAPLANTIO MANUAL 1.110 plantas/HA, mudas com tratamento (MAP e Cupinicida), mudas SEM TUBETE + ReplantioRosa Maria363Principal16Julho-260846195,67983796346194 | AM7: =IFERROR(V7/W7,"") -> 0.64935065 | AN7: =IFERROR(AM7*Z7,"") -> 803.50649 | AO7: =Z7*T7 -> 19798.4 | AP7: =IFERROR(AO7-AN7,"") -> 18994.894
A8: 46435 | B8: 46194 | C8: 1°- 07/2026 | D8: GN1400 | E8: Arauco - Silvicultura | F8: Operador de Trator de Pneu | G8: 8 | H8: 10859 | I8: RENATO DE SOUZA PEREIRA | J8: 10093 | K8: JONATHAN FONSECA DE OLIVEIRA | L8: JONATHAN FONSECA DE OLIVEIRA | M8: REF11 | N8: SUBSOLAGEM COM ADUBAÇÃO 350 a 400kg/ha, 40 a 50cm de profundidade, com bacia 3 a 4 litros, 2 turnos | O8: HA | P8: 400 | Q8: Rosa Maria | R8: 378 | S8: 2 | T8: 6.93 | U8: 0 | V8: 2 | W8: 1.59 | X8: 0.29 | Y8: 0.29 | Z8: 1104.72 | AA8: CONCLUIDO | AB8: Principal | AC8: Jonathan Fonseca de Oliveira | AE8: 46194.843 | AF8: máquinas 282 trabalhou 8 horas | AG8: =IF(B8=0,"",PROPER(TEXT(IF(DAY(B8)>20,EDATE(B8,1),B8),"MMMM-aa"))) -> Julho-26 | AH8: =_xlfn.XLOOKUP(AK8,'Base de Preços'!P$7:P$3001,'Base de Preços'!J$7:J$3001,"",0) -> 1263.67 | AI8: =IF(AB8="Principal",AH8*T8,0) -> 8757.2331 | AJ8: =_xlfn.XLOOKUP(N8,Agrupamentos!C$3:C$496,Agrupamentos!D$3:D$496,"",0) -> SUBSOSALGEM | AK8: =N8&D8&M8 -> SUBSOLAGEM COM ADUBAÇÃO 350 a 400kg/ha, 40 a 50cm de profundidade, com bacia 3 a 4 litros, 2 turnosGN1400REF11 | AL8: =CONCATENATE(A8,D8,F8,K8,N8,Q8,R8,AB8,T8,AG8,U8,V8,AE8,B8) -> 46435GN1400Operador de Trator de PneuJONATHAN FONSECA DE OLIVEIRASUBSOLAGEM COM ADUBAÇÃO 350 a 400kg/ha, 40 a 50cm de profundidade, com bacia 3 a 4 litros, 2 turnosRosa Maria378Principal6,93Julho-260246194,843148148146194 | AM8: =IFERROR(V8/W8,"") -> 1.2578616 | AN8: =IFERROR(AM8*Z8,"") -> 1389.5849 | AO8: =Z8*T8 -> 7655.7096 | AP8: =IFERROR(AO8-AN8,"") -> 6266.1247
A9: 46435 | B9: 46194 | C9: 1°- 07/2026 | D9: GN1400 | E9: Arauco - Silvicultura | F9: Operador de Trator de Pneu | G9: 8 | H9: 10859 | I9: RENATO DE SOUZA PEREIRA | J9: 10093 | K9: JONATHAN FONSECA DE OLIVEIRA | L9: JONATHAN FONSECA DE OLIVEIRA | M9: REF12 | N9: PLANTIO MANUAL 1.110 plantas/HA, mudas com tratamento (MAP e Cupinicida), mudas SEM TUBETE + Replantio | O9: HA | P9: 400 | Q9: Rosa Maria | R9: 364 | S9: 6 | T9: 14.17 | U9: 0 | V9: 6 | W9: 1.23 | X9: 0.42 | Y9: 0.42 | Z9: 389.89 | AA9: CONCLUIDO | AB9: Suporte | AC9: Jonathan Fonseca de Oliveira | AE9: 46194.843 | AF9: máquinas 282 trabalhou 8 horas | AG9: =IF(B9=0,"",PROPER(TEXT(IF(DAY(B9)>20,EDATE(B9,1),B9),"MMMM-aa"))) -> Julho-26 | AH9: =_xlfn.XLOOKUP(AK9,'Base de Preços'!P$7:P$3001,'Base de Preços'!J$7:J$3001,"",0) -> 1627.29 | AI9: =IF(AB9="Principal",AH9*T9,0) -> 0 | AJ9: =_xlfn.XLOOKUP(N9,Agrupamentos!C$3:C$496,Agrupamentos!D$3:D$496,"",0) -> PLANTIO | AK9: =N9&D9&M9 -> PLANTIO MANUAL 1.110 plantas/HA, mudas com tratamento (MAP e Cupinicida), mudas SEM TUBETE + ReplantioGN1400REF12 | AL9: =CONCATENATE(A9,D9,F9,K9,N9,Q9,R9,AB9,T9,AG9,U9,V9,AE9,B9) -> 46435GN1400Operador de Trator de PneuJONATHAN FONSECA DE OLIVEIRAPLANTIO MANUAL 1.110 plantas/HA, mudas com tratamento (MAP e Cupinicida), mudas SEM TUBETE + ReplantioRosa Maria364Suporte14,17Julho-260646194,843148148146194 | AM9: =IFERROR(V9/W9,"") -> 4.8780488 | AN9: =IFERROR(AM9*Z9,"") -> 1901.9024 | AO9: =Z9*T9 -> 5524.7413 | AP9: =IFERROR(AO9-AN9,"") -> 3622.8389
A10: 46438 | B10: 46194 | C10: 1°- 07/2026 | D10: GN1400 | E10: Arauco - Silvicultura | F10: Motorista de Caminhão Pipa | G10: 8 | H10: 10859 | I10: RENATO DE SOUZA PEREIRA | J10: 10315 | K10: ANTONIO MARCIO PEREIRA DA SILVA | L10: ANTONIO MARCIO PEREIRA DA SILVA | M10: 43 | N10: APOIO E MANUTEÇÃO | O10: HA | P10: 410 | Q10: Canto do Pinhe | R10: 509 | S10: 0 | T10: 0 | U10: 8 | V10: 8 | W10: 0 | X10: 0 | Y10: 0 | Z10: 0 | AA10: EM ANDAMENTO | AB10: Suporte | AC10: Antonio Marcio Pereira da Silva | AD10: Leandra de Miranda Souza Costa | AE10: 46194.899 | AG10: =IF(B10=0,"",PROPER(TEXT(IF(DAY(B10)>20,EDATE(B10,1),B10),"MMMM-aa"))) -> Julho-26 | AH10: =_xlfn.XLOOKUP(AK10,'Base de Preços'!P$7:P$3001,'Base de Preços'!J$7:J$3001,"",0) -> 0 | AI10: =IF(AB10="Principal",AH10*T10,0) -> 0 | AJ10: =_xlfn.XLOOKUP(N10,Agrupamentos!C$3:C$496,Agrupamentos!D$3:D$496,"",0) -> APOIO E MANUTENÇÃO | AK10: =N10&D10&M10 -> APOIO E MANUTEÇÃOGN140043 | AL10: =CONCATENATE(A10,D10,F10,K10,N10,Q10,R10,AB10,T10,AG10,U10,V10,AE10,B10) -> 46438GN1400Motorista de Caminhão PipaANTONIO MARCIO PEREIRA DA SILVAAPOIO E MANUTEÇÃOCanto do Pinhe509Suporte0Julho-268846194,898564814846194 | AM10: =IFERROR(V10/W10,"") | AN10: =IFERROR(AM10*Z10,"") | AO10: =Z10*T10 -> 0 | AP10: =IFERROR(AO10-AN10,"")
A11: 46438 | B11: 46194 | C11: 1°- 07/2026 | D11: GN1400 | E11: Arauco - Silvicultura | F11: Operador de Trator de Pneu | G11: 8 | H11: 10859 | I11: RENATO DE SOUZA PEREIRA | J11: 10315 | K11: ANTONIO MARCIO PEREIRA DA SILVA | L11: ANTONIO MARCIO PEREIRA DA SILVA | M11: 43 | N11: APOIO E MANUTEÇÃO | O11: HA | P11: 410 | Q11: Canto do Pinhe | R11: 509 | S11: 0 | T11: 0 | U11: 8 | V11: 8 | W11: 0 | X11: 0 | Y11: 0 | Z11: 0 | AA11: EM ANDAMENTO | AB11: Suporte | AC11: Antonio Marcio Pereira da Silva | AD11: Leandra de Miranda Souza Costa | AE11: 46194.899 | AG11: =IF(B11=0,"",PROPER(TEXT(IF(DAY(B11)>20,EDATE(B11,1),B11),"MMMM-aa"))) -> Julho-26 | AH11: =_xlfn.XLOOKUP(AK11,'Base de Preços'!P$7:P$3001,'Base de Preços'!J$7:J$3001,"",0) -> 0 | AI11: =IF(AB11="Principal",AH11*T11,0) -> 0 | AJ11: =_xlfn.XLOOKUP(N11,Agrupamentos!C$3:C$496,Agrupamentos!D$3:D$496,"",0) -> APOIO E MANUTENÇÃO | AK11: =N11&D11&M11 -> APOIO E MANUTEÇÃOGN140043 | AL11: =CONCATENATE(A11,D11,F11,K11,N11,Q11,R11,AB11,T11,AG11,U11,V11,AE11,B11) -> 46438GN1400Operador de Trator de PneuANTONIO MARCIO PEREIRA DA SILVAAPOIO E MANUTEÇÃOCanto do Pinhe509Suporte0Julho-268846194,898564814846194 | AM11: =IFERROR(V11/W11,"") | AN11: =IFERROR(AM11*Z11,"") | AO11: =Z11*T11 -> 0 | AP11: =IFERROR(AO11-AN11,"")
A12: 46489 | B12: 46194 | C12: 1°- 07/2026 | D12: GN1410 | E12: MS Florestal - Silvicultura | F12: Trabalhador Florestal | G12: 8 | H12: 11331 | I12: JOSE VITOR MORAES SANTOS | J12: 11752 | K12: MATEUS SANCHES PERES BIENIEK | L12: MATEUS SANCHES PERES BIENIEK | M12: 1 | N12: APOIO E MANUTEÇÃO 1410 | O12: HA | P12: 484 | Q12: SÃO PEDRO III | R12: T001-01 | S12: 0 | T12: 0 | U12: 8 | V12: 8 | W12: 0 | X12: 0 | Y12: 0 | Z12: 0 | AA12: EM ANDAMENTO | AB12: Suporte | AC12: Mateus Sanches Peres Bieniek | AE12: 46195.787 | AG12: =IF(B12=0,"",PROPER(TEXT(IF(DAY(B12)>20,EDATE(B12,1),B12),"MMMM-aa"))) -> Julho-26 | AH12: =_xlfn.XLOOKUP(AK12,'Base de Preços'!P$7:P$3001,'Base de Preços'!J$7:J$3001,"",0) -> 0 | AI12: =IF(AB12="Principal",AH12*T12,0) -> 0 | AJ12: =_xlfn.XLOOKUP(N12,Agrupamentos!C$3:C$496,Agrupamentos!D$3:D$496,"",0) -> APOIO E MANUTENÇÃO | AK12: =N12&D12&M12 -> APOIO E MANUTEÇÃO 1410GN14101 | AL12: =CONCATENATE(A12,D12,F12,K12,N12,Q12,R12,AB12,T12,AG12,U12,V12,AE12,B12) -> 46489GN1410Trabalhador FlorestalMATEUS SANCHES PERES BIENIEKAPOIO E MANUTEÇÃO 1410SÃO PEDRO IIIT001-01Suporte0Julho-268846195,786909722246194 | AM12: =IFERROR(V12/W12,"") | AN12: =IFERROR(AM12*Z12,"") | AO12: =Z12*T12 -> 0 | AP12: =IFERROR(AO12-AN12,"")
A13: 46489 | B13: 46194 | C13: 1°- 07/2026 | D13: GN1410 | E13: MS Florestal - Silvicultura | F13: Operador de Trator de Pneu | G13: 8 | H13: 11331 | I13: JOSE VITOR MORAES SANTOS | J13: 11752 | K13: MATEUS SANCHES PERES BIENIEK | L13: MATEUS SANCHES PERES BIENIEK | M13: 1 | N13: APOIO E MANUTEÇÃO 1410 | O13: HA | P13: 484 | Q13: SÃO PEDRO III | R13: T001-01 | S13: 0 | T13: 0 | U13: 16 | V13: 16 | W13: 0 | X13: 0 | Y13: 0 | Z13: 0 | AA13: EM ANDAMENTO | AB13: Suporte | AC13: Mateus Sanches Peres Bieniek | AE13: 46195.787 | AG13: =IF(B13=0,"",PROPER(TEXT(IF(DAY(B13)>20,EDATE(B13,1),B13),"MMMM-aa"))) -> Julho-26 | AH13: =_xlfn.XLOOKUP(AK13,'Base de Preços'!P$7:P$3001,'Base de Preços'!J$7:J$3001,"",0) -> 0 | AI13: =IF(AB13="Principal",AH13*T13,0) -> 0 | AJ13: =_xlfn.XLOOKUP(N13,Agrupamentos!C$3:C$496,Agrupamentos!D$3:D$496,"",0) -> APOIO E MANUTENÇÃO | AK13: =N13&D13&M13 -> APOIO E MANUTEÇÃO 1410GN14101 | AL13: =CONCATENATE(A13,D13,F13,K13,N13,Q13,R13,AB13,T13,AG13,U13,V13,AE13,B13) -> 46489GN1410Operador de Trator de PneuMATEUS SANCHES PERES BIENIEKAPOIO E MANUTEÇÃO 1410SÃO PEDRO IIIT001-01Suporte0Julho-26161646195,786909722246194 | AM13: =IFERROR(V13/W13,"") | AN13: =IFERROR(AM13*Z13,"") | AO13: =Z13*T13 -> 0 | AP13: =IFERROR(AO13-AN13,"")
A14: 46489 | B14: 46194 | C14: 1°- 07/2026 | D14: GN1410 | E14: MS Florestal - Silvicultura | F14: Operador de Trator de Pneu | G14: 8 | H14: 11331 | I14: JOSE VITOR MORAES SANTOS | J14: 11752 | K14: MATEUS SANCHES PERES BIENIEK | L14: MATEUS SANCHES PERES BIENIEK | M14: 1 | N14: APOIO E MANUTEÇÃO 1410 | O14: HA | P14: 503 | Q14: MÃE SANTA GLEBA A | R14: 007-01 | S14: 0 | T14: 0 | U14: 24 | V14: 24 | W14: 0 | X14: 0 | Y14: 0 | Z14: 0 | AA14: EM ANDAMENTO | AB14: Suporte | AC14: Mateus Sanches Peres Bieniek | AD14: Vanessa Maria da Silva | AE14: 46195.787 | AG14: =IF(B14=0,"",PROPER(TEXT(IF(DAY(B14)>20,EDATE(B14,1),B14),"MMMM-aa"))) -> Julho-26 | AH14: =_xlfn.XLOOKUP(AK14,'Base de Preços'!P$7:P$3001,'Base de Preços'!J$7:J$3001,"",0) -> 0 | AI14: =IF(AB14="Principal",AH14*T14,0) -> 0 | AJ14: =_xlfn.XLOOKUP(N14,Agrupamentos!C$3:C$496,Agrupamentos!D$3:D$496,"",0) -> APOIO E MANUTENÇÃO | AK14: =N14&D14&M14 -> APOIO E MANUTEÇÃO 1410GN14101 | AL14: =CONCATENATE(A14,D14,F14,K14,N14,Q14,R14,AB14,T14,AG14,U14,V14,AE14,B14) -> 46489GN1410Operador de Trator de PneuMATEUS SANCHES PERES BIENIEKAPOIO E MANUTEÇÃO 1410MÃE SANTA GLEBA A007-01Suporte0Julho-26242446195,786909722246194 | AM14: =IFERROR(V14/W14,"") | AN14: =IFERROR(AM14*Z14,"") | AO14: =Z14*T14 -> 0 | AP14: =IFERROR(AO14-AN14,"")
A15: 46489 | B15: 46194 | C15: 1°- 07/2026 | D15: GN1410 | E15: MS Florestal - Silvicultura | F15: Trabalhador Florestal | G15: 8 | H15: 11331 | I15: JOSE VITOR MORAES SANTOS | J15: 11752 | K15: MATEUS SANCHES PERES BIENIEK | L15: MATEUS SANCHES PERES BIENIEK | M15: 1 | N15: APOIO E MANUTEÇÃO 1410 | O15: HA | P15: 503 | Q15: MÃE SANTA GLEBA A | R15: 007-01 | S15: 0 | T15: 0 | U15: 8 | V15: 8 | W15: 0 | X15: 0 | Y15: 0 | Z15: 0 | AA15: EM ANDAMENTO | AB15: Suporte | AC15: Mateus Sanches Peres Bieniek | AE15: 46195.787 | AG15: =IF(B15=0,"",PROPER(TEXT(IF(DAY(B15)>20,EDATE(B15,1),B15),"MMMM-aa"))) -> Julho-26 | AH15: =_xlfn.XLOOKUP(AK15,'Base de Preços'!P$7:P$3001,'Base de Preços'!J$7:J$3001,"",0) -> 0 | AI15: =IF(AB15="Principal",AH15*T15,0) -> 0 | AJ15: =_xlfn.XLOOKUP(N15,Agrupamentos!C$3:C$496,Agrupamentos!D$3:D$496,"",0) -> APOIO E MANUTENÇÃO | AK15: =N15&D15&M15 -> APOIO E MANUTEÇÃO 1410GN14101 | AL15: =CONCATENATE(A15,D15,F15,K15,N15,Q15,R15,AB15,T15,AG15,U15,V15,AE15,B15) -> 46489GN1410Trabalhador FlorestalMATEUS SANCHES PERES BIENIEKAPOIO E MANUTEÇÃO 1410MÃE SANTA GLEBA A007-01Suporte0Julho-268846195,786909722246194 | AM15: =IFERROR(V15/W15,"") | AN15: =IFERROR(AM15*Z15,"") | AO15: =Z15*T15 -> 0 | AP15: =IFERROR(AO15-AN15,"")
A16: 46491 | B16: 46194 | C16: 1°- 07/2026 | D16: GN1410 | E16: MS Florestal - Silvicultura | F16: Operador de Trator de Pneu | G16: 8 | H16: 11065 | I16: LUCAS SANTOS MORAIS | J16: 11078 | K16: NATAN SANTOS MORAIS | L16: NATAN SANTOS MORAIS | M16: REF223 | N16: SERV HORA TRATOR PNEU 100CV AGRIC | O16: H | P16: 503 | Q16: MÃE SANTA GLEBA A | R16: 001-01 | S16: 24 | T16: 24 | U16: 0 | V16: 24 | W16: 0 | X16: 1 | Y16: 1 | Z16: 290.54 | AA16: EM ANDAMENTO | AB16: Principal | AC16: Natan Santos Morais | AE16: 46195.802 | AG16: =IF(B16=0,"",PROPER(TEXT(IF(DAY(B16)>20,EDATE(B16,1),B16),"MMMM-aa"))) -> Julho-26 | AH16: =_xlfn.XLOOKUP(AK16,'Base de Preços'!P$7:P$3001,'Base de Preços'!J$7:J$3001,"",0) -> 290.54 | AI16: =IF(AB16="Principal",AH16*T16,0) -> 6972.96 | AJ16: =_xlfn.XLOOKUP(N16,Agrupamentos!C$3:C$496,Agrupamentos!D$3:D$496,"",0) -> HORA TRATOR | AK16: =N16&D16&M16 -> SERV HORA TRATOR PNEU 100CV AGRICGN1410REF223 | AL16: =CONCATENATE(A16,D16,F16,K16,N16,Q16,R16,AB16,T16,AG16,U16,V16,AE16,B16) -> 46491GN1410Operador de Trator de PneuNATAN SANTOS MORAISSERV HORA TRATOR PNEU 100CV AGRICMÃE SANTA GLEBA A001-01Principal24Julho-2602446195,802418981546194 | AM16: =IFERROR(V16/W16,"") | AN16: =IFERROR(AM16*Z16,"") | AO16: =Z16*T16 -> 6972.96 | AP16: =IFERROR(AO16-AN16,"")
A17: 46491 | B17: 46194 | C17: 1°- 07/2026 | D17: GN1410 | E17: MS Florestal - Silvicultura | F17: Motorista | G17: 8 | H17: 11065 | I17: LUCAS SANTOS MORAIS | J17: 11078 | K17: NATAN SANTOS MORAIS | L17: NATAN SANTOS MORAIS | M17: 1 | N17: APOIO E MANUTEÇÃO 1410 | O17: HA | P17: 503 | Q17: MÃE SANTA GLEBA A | R17: 001-01 | S17: 16 | T17: 0 | U17: 8 | V17: 24 | W17: 0 | X17: 0 | Y17: 0 | Z17: 0 | AA17: EM ANDAMENTO | AB17: Principal | AC17: Natan Santos Morais | AD17: Vanessa Maria da Silva | AE17: 46195.802 | AG17: =IF(B17=0,"",PROPER(TEXT(IF(DAY(B17)>20,EDATE(B17,1),B17),"MMMM-aa"))) -> Julho-26 | AH17: =_xlfn.XLOOKUP(AK17,'Base de Preços'!P$7:P$3001,'Base de Preços'!J$7:J$3001,"",0) -> 0 | AI17: =IF(AB17="Principal",AH17*T17,0) -> 0 | AJ17: =_xlfn.XLOOKUP(N17,Agrupamentos!C$3:C$496,Agrupamentos!D$3:D$496,"",0) -> APOIO E MANUTENÇÃO | AK17: =N17&D17&M17 -> APOIO E MANUTEÇÃO 1410GN14101 | AL17: =CONCATENATE(A17,D17,F17,K17,N17,Q17,R17,AB17,T17,AG17,U17,V17,AE17,B17) -> 46491GN1410MotoristaNATAN SANTOS MORAISAPOIO E MANUTEÇÃO 1410MÃE SANTA GLEBA A001-01Principal0Julho-2682446195,802418981546194 | AM17: =IFERROR(V17/W17,"") | AN17: =IFERROR(AM17*Z17,"") | AO17: =Z17*T17 -> 0 | AP17: =IFERROR(AO17-AN17,"")
A18: 48044 | B18: 46194 | C18: 1°- 07/2026 | D18: GN1410 | E18: MS Florestal - Silvicultura | F18: Operador de Trator de Pneu | G18: 8 | H18: 11065 | I18: LUCAS SANTOS MORAIS | J18: 11390 | K18: DIEMISSON DE ALMEIDA SANTOS | L18: DIEMISSON DE ALMEIDA SANTOS | M18: 1 | N18: APOIO E MANUTEÇÃO 1410 | O18: HA | P18: 952 | Q18: MONTE BELO GLEBA B - | R18: 016-01 | S18: 0 | T18: 0 | U18: 8 | V18: 8 | W18: 0 | X18: 0 | Y18: 0 | Z18: 0 | AA18: EM ANDAMENTO | AB18: Suporte | AC18: Mateus Sanches Peres Bieniek | AD18: Mateus Sanches Peres Bieniek | AE18: 46225.585 | AG18: =IF(B18=0,"",PROPER(TEXT(IF(DAY(B18)>20,EDATE(B18,1),B18),"MMMM-aa"))) -> Julho-26 | AH18: =_xlfn.XLOOKUP(AK18,'Base de Preços'!P$7:P$3001,'Base de Preços'!J$7:J$3001,"",0) -> 0 | AI18: =IF(AB18="Principal",AH18*T18,0) -> 0 | AJ18: =_xlfn.XLOOKUP(N18,Agrupamentos!C$3:C$496,Agrupamentos!D$3:D$496,"",0) -> APOIO E MANUTENÇÃO | AK18: =N18&D18&M18 -> APOIO E MANUTEÇÃO 1410GN14101 | AL18: =CONCATENATE(A18,D18,F18,K18,N18,Q18,R18,AB18,T18,AG18,U18,V18,AE18,B18) -> 48044GN1410Operador de Trator de PneuDIEMISSON DE ALMEIDA SANTOSAPOIO E MANUTEÇÃO 1410MONTE BELO GLEBA B -016-01Suporte0Julho-268846225,585023148146194 | AM18: =IFERROR(V18/W18,"") | AN18: =IFERROR(AM18*Z18,"") | AO18: =Z18*T18 -> 0 | AP18: =IFERROR(AO18-AN18,"")
A19: 46481 | B19: 46195 | C19: 1°- 07/2026 | D19: GN1270 | E19: Lacan Florestal | F19: Motorista | G19: 8 | H19: 11697 | I19: ADRIANO BARROS DA COSTA | J19: 11067 | K19: FABIO MATOS DE SOUZA | L19: FABIO MATOS DE SOUZA | M19: 2 | N19: APOIO E MANUTEÇÃO | O19: HA | P19: 371 | Q19: Nova Esperança | R19: 1 | S19: 8 | T19: 0 | U19: 0 | V19: 8 | W19: 0 | X19: 0 | Y19: 0 | Z19: 0 | AA19: CONCLUIDO | AB19: Suporte | AC19: Fabio Matos de Souza | AD19: Leandra de Miranda Souza Costa | AE19: 46195.723 | AG19: =IF(B19=0,"",PROPER(TEXT(IF(DAY(B19)>20,EDATE(B19,1),B19),"MMMM-aa"))) -> Julho-26 | AH19: =_xlfn.XLOOKUP(AK19,'Base de Preços'!P$7:P$3001,'Base de Preços'!J$7:J$3001,"",0) -> 0 | AI19: =IF(AB19="Principal",AH19*T19,0) -> 0 | AJ19: =_xlfn.XLOOKUP(N19,Agrupamentos!C$3:C$496,Agrupamentos!D$3:D$496,"",0) -> APOIO E MANUTENÇÃO | AK19: =N19&D19&M19 -> APOIO E MANUTEÇÃOGN12702 | AL19: =CONCATENATE(A19,D19,F19,K19,N19,Q19,R19,AB19,T19,AG19,U19,V19,AE19,B19) -> 46481GN1270MotoristaFABIO MATOS DE SOUZAAPOIO E MANUTEÇÃONova Esperança1Suporte0Julho-260846195,723194444446195 | AM19: =IFERROR(V19/W19,"") | AN19: =IFERROR(AM19*Z19,"") | AO19: =Z19*T19 -> 0 | AP19: =IFERROR(AO19-AN19,"")
A20: 46481 | B20: 46195 | C20: 1°- 07/2026 | D20: GN1270 | E20: Lacan Florestal | F20: Trabalhador Florestal | G20: 8 | H20: 11697 | I20: ADRIANO BARROS DA COSTA | J20: 11067 | K20: FABIO MATOS DE SOUZA | L20: FABIO MATOS DE SOUZA | M20: 70 | N20: COMBATE A FORMIGA MANUAL MANUTENÇÃO - ANO 01 | O20: HA | P20: 371 | Q20: Nova Esperança | R20: 7 | S20: 104 | T20: 86.94 | U20: 0 | V20: 104 | W20: 1.42 | X20: 1.2 | Y20: 1.2 | Z20: 149.09 | AA20: CONCLUIDO | AB20: Principal | AC20: Fabio Matos de Souza | AD20: Leandra de Miranda Souza Costa | AE20: 46195.723 | AG20: =IF(B20=0,"",PROPER(TEXT(IF(DAY(B20)>20,EDATE(B20,1),B20),"MMMM-aa"))) -> Julho-26 | AH20: =_xlfn.XLOOKUP(AK20,'Base de Preços'!P$7:P$3001,'Base de Preços'!J$7:J$3001,"",0) -> 152.18 | AI20: =IF(AB20="Principal",AH20*T20,0) -> 13230.529 | AJ20: =_xlfn.XLOOKUP(N20,Agrupamentos!C$3:C$496,Agrupamentos!D$3:D$496,"",0) -> COMBATE A FORMIGA MANUAL | AK20: =N20&D20&M20 -> COMBATE A FORMIGA MANUAL MANUTENÇÃO - ANO 01GN127070 | AL20: =CONCATENATE(A20,D20,F20,K20,N20,Q20,R20,AB20,T20,AG20,U20,V20,AE20,B20) -> 46481GN1270Trabalhador FlorestalFABIO MATOS DE SOUZACOMBATE A FORMIGA MANUAL MANUTENÇÃO - ANO 01Nova Esperança7Principal86,94Julho-26010446195,723194444446195 | AM20: =IFERROR(V20/W20,"") -> 73.239437 | AN20: =IFERROR(AM20*Z20,"") -> 10919.268 | AO20: =Z20*T20 -> 12961.885 | AP20: =IFERROR(AO20-AN20,"") -> 2042.617
A21: 46481 | B21: 46195 | C21: 1°- 07/2026 | D21: GN1270 | E21: Lacan Florestal | F21: Operador de Máquina Pesada | G21: 8 | H21: 11697 | I21: ADRIANO BARROS DA COSTA | J21: 11067 | K21: FABIO MATOS DE SOUZA | L21: FABIO MATOS DE SOUZA | M21: 2 | N21: APOIO E MANUTEÇÃO | O21: HA | P21: 371 | Q21: Nova Esperança | R21: 1 | S21: 0 | T21: 0 | U21: 8 | V21: 8 | W21: 0 | X21: 0 | Y21: 0 | Z21: 0 | AA21: EM ANDAMENTO | AB21: Suporte | AC21: Fabio Matos de Souza | AD21: Leandra de Miranda Souza Costa | AE21: 46196.366 | AG21: =IF(B21=0,"",PROPER(TEXT(IF(DAY(B21)>20,EDATE(B21,1),B21),"MMMM-aa"))) -> Julho-26 | AH21: =_xlfn.XLOOKUP(AK21,'Base de Preços'!P$7:P$3001,'Base de Preços'!J$7:J$3001,"",0) -> 0 | AI21: =IF(AB21="Principal",AH21*T21,0) -> 0 | AJ21: =_xlfn.XLOOKUP(N21,Agrupamentos!C$3:C$496,Agrupamentos!D$3:D$496,"",0) -> APOIO E MANUTENÇÃO | AK21: =N21&D21&M21 -> APOIO E MANUTEÇÃOGN12702 | AL21: =CONCATENATE(A21,D21,F21,K21,N21,Q21,R21,AB21,T21,AG21,U21,V21,AE21,B21) -> 46481GN1270Operador de Máquina PesadaFABIO MATOS DE SOUZAAPOIO E MANUTEÇÃONova Esperança1Suporte0Julho-268846196,366388888946195 | AM21: =IFERROR(V21/W21,"") | AN21: =IFERROR(AM21*Z21,"") | AO21: =Z21*T21 -> 0 | AP21: =IFERROR(AO21-AN21,"")
A22: 46481 | B22: 46195 | C22: 1°- 07/2026 | D22: GN1270 | E22: Lacan Florestal | F22: Trabalhador Florestal | G22: 8 | H22: 11697 | I22: ADRIANO BARROS DA COSTA | J22: 11067 | K22: FABIO MATOS DE SOUZA | L22: FABIO MATOS DE SOUZA | M22: 70 | N22: COMBATE A FORMIGA MANUAL MANUTENÇÃO - ANO 01 | O22: HA | P22: 371 | Q22: Nova Esperança | R22: 1 | S22: 112 | T22: 76.34 | U22: 0 | V22: 112 | W22: 1.42 | X22: 1.47 | Y22: 1.47 | Z22: 149.09 | AA22: CONCLUIDO | AB22: Principal | AC22: Fabio Matos de Souza | AD22: Leandra de Miranda Souza Costa | AE22: 46195.723 | AG22: =IF(B22=0,"",PROPER(TEXT(IF(DAY(B22)>20,EDATE(B22,1),B22),"MMMM-aa"))) -> Julho-26 | AH22: =_xlfn.XLOOKUP(AK22,'Base de Preços'!P$7:P$3001,'Base de Preços'!J$7:J$3001,"",0) -> 152.18 | AI22: =IF(AB22="Principal",AH22*T22,0) -> 11617.421 | AJ22: =_xlfn.XLOOKUP(N22,Agrupamentos!C$3:C$496,Agrupamentos!D$3:D$496,"",0) -> COMBATE A FORMIGA MANUAL | AK22: =N22&D22&M22 -> COMBATE A FORMIGA MANUAL MANUTENÇÃO - ANO 01GN127070 | AL22: =CONCATENATE(A22,D22,F22,K22,N22,Q22,R22,AB22,T22,AG22,U22,V22,AE22,B22) -> 46481GN1270Trabalhador FlorestalFABIO MATOS DE SOUZACOMBATE A FORMIGA MANUAL MANUTENÇÃO - ANO 01Nova Esperança1Principal76,34Julho-26011246195,723194444446195 | AM22: =IFERROR(V22/W22,"") -> 78.873239 | AN22: =IFERROR(AM22*Z22,"") -> 11759.211 | AO22: =Z22*T22 -> 11381.531 | AP22: =IFERROR(AO22-AN22,"") -> -377.68067
A23: 46533 | B23: 46195 | C23: 1°- 07/2026 | D23: GN1270 | E23: Lacan Florestal | F23: Motorista | G23: 8 | H23: 9241 | I23: SILMAR BARBOSA DOS SANTOS | J23: 11447 | K23: ANDREY NICOLLAS UCHOA DE OLIVEIRA | L23: Apoio e Manutenção GN1270 | M23: 2 | N23: APOIO E MANUTEÇÃO | O23: HA | P23: 390 | Q23: Pátio MS | R23: T01 | S23: 0 | T23: 0 | U23: 8 | V23: 8 | W23: 0 | X23: 0 | Y23: 0 | Z23: 0 | AA23: CONCLUIDO | AB23: Suporte | AC23: Andrey Nicollas Uchôa de Oliveira | AD23: Leandra de Miranda Souza Costa | AE23: 46196.375 | AG23: =IF(B23=0,"",PROPER(TEXT(IF(DAY(B23)>20,EDATE(B23,1),B23),"MMMM-aa"))) -> Julho-26 | AH23: =_xlfn.XLOOKUP(AK23,'Base de Preços'!P$7:P$3001,'Base de Preços'!J$7:J$3001,"",0) -> 0 | AI23: =IF(AB23="Principal",AH23*T23,0) -> 0 | AJ23: =_xlfn.XLOOKUP(N23,Agrupamentos!C$3:C$496,Agrupamentos!D$3:D$496,"",0) -> APOIO E MANUTENÇÃO | AK23: =N23&D23&M23 -> APOIO E MANUTEÇÃOGN12702 | AL23: =CONCATENATE(A23,D23,F23,K23,N23,Q23,R23,AB23,T23,AG23,U23,V23,AE23,B23) -> 46533GN1270MotoristaANDREY NICOLLAS UCHOA DE OLIVEIRAAPOIO E MANUTEÇÃOPátio MST01Suporte0Julho-268846196,375370370446195 | AM23: =IFERROR(V23/W23,"") | AN23: =IFERROR(AM23*Z23,"") | AO23: =Z23*T23 -> 0 | AP23: =IFERROR(AO23-AN23,"")
A24: 46495 | B24: 46195 | C24: 1°- 07/2026 | D24: GN1400 | E24: Arauco - Silvicultura | F24: Trabalhador Florestal | G24: 8 | H24: 10859 | I24: RENATO DE SOUZA PEREIRA | J24: 9900 | K24: CARLOS ALVES DOS SANTOS | L24: CARLOS ALVES DOS SANTOS | M24: 43 | N24: APOIO E MANUTEÇÃO | O24: HA | P24: 496 | Q24: Santa Beatriz | R24: 22 | S24: 0 | T24: 0 | U24: 0 | V24: 0 | W24: 0 | X24: 0 | Y24: 0 | Z24: 0 | AA24: CONCLUIDO | AB24: Suporte | AC24: Carlos Alves dos Santos | AD24: Cilas Andrei da Silva Serrado | AE24: 46195.853 | AF24: ATIVIDADE JA RECEBIDA NA COMP 06 | AG24: =IF(B24=0,"",PROPER(TEXT(IF(DAY(B24)>20,EDATE(B24,1),B24),"MMMM-aa"))) -> Julho-26 | AH24: =_xlfn.XLOOKUP(AK24,'Base de Preços'!P$7:P$3001,'Base de Preços'!J$7:J$3001,"",0) -> 0 | AI24: =IF(AB24="Principal",AH24*T24,0) -> 0 | AJ24: =_xlfn.XLOOKUP(N24,Agrupamentos!C$3:C$496,Agrupamentos!D$3:D$496,"",0) -> APOIO E MANUTENÇÃO | AK24: =N24&D24&M24 -> APOIO E MANUTEÇÃOGN140043 | AL24: =CONCATENATE(A24,D24,F24,K24,N24,Q24,R24,AB24,T24,AG24,U24,V24,AE24,B24) -> 46495GN1400Trabalhador FlorestalCARLOS ALVES DOS SANTOSAPOIO E MANUTEÇÃOSanta Beatriz22Suporte0Julho-260046195,853391203746195 | AM24: =IFERROR(V24/W24,"") | AN24: =IFERROR(AM24*Z24,"") | AO24: =Z24*T24 -> 0 | AP24: =IFERROR(AO24-AN24,"")
A25: 46495 | B25: 46195 | C25: 1°- 07/2026 | D25: GN1400 | E25: Arauco - Silvicultura | F25: Operador de Trator de Pneu | G25: 8 | H25: 10859 | I25: RENATO DE SOUZA PEREIRA | J25: 9900 | K25: CARLOS ALVES DOS SANTOS | L25: CARLOS ALVES DOS SANTOS | M25: 43 | N25: APOIO E MANUTEÇÃO | O25: HA | P25: 496 | Q25: Santa Beatriz | R25: 26 | S25: 0 | T25: 0 | U25: 0 | V25: 0 | W25: 0 | X25: 0 | Y25: 0 | Z25: 0 | AA25: CONCLUIDO | AB25: Suporte | AC25: Carlos Alves dos Santos | AD25: Cilas Andrei da Silva Serrado | AE25: 46195.853 | AF25: ATIVIDADE JA RECEBIDA NA COMP 06 | AG25: =IF(B25=0,"",PROPER(TEXT(IF(DAY(B25)>20,EDATE(B25,1),B25),"MMMM-aa"))) -> Julho-26 | AH25: =_xlfn.XLOOKUP(AK25,'Base de Preços'!P$7:P$3001,'Base de Preços'!J$7:J$3001,"",0) -> 0 | AI25: =IF(AB25="Principal",AH25*T25,0) -> 0 | AJ25: =_xlfn.XLOOKUP(N25,Agrupamentos!C$3:C$496,Agrupamentos!D$3:D$496,"",0) -> APOIO E MANUTENÇÃO | AK25: =N25&D25&M25 -> APOIO E MANUTEÇÃOGN140043 | AL25: =CONCATENATE(A25,D25,F25,K25,N25,Q25,R25,AB25,T25,AG25,U25,V25,AE25,B25) -> 46495GN1400Operador de Trator de PneuCARLOS ALVES DOS SANTOSAPOIO E MANUTEÇÃOSanta Beatriz26Suporte0Julho-260046195,853391203746195 | AM25: =IFERROR(V25/W25,"") | AN25: =IFERROR(AM25*Z25,"") | AO25: =Z25*T25 -> 0 | AP25: =IFERROR(AO25-AN25,"")
A26: 46495 | B26: 46195 | C26: 1°- 07/2026 | D26: GN1400 | E26: Arauco - Silvicultura | F26: Operador de Trator de Pneu | G26: 8 | H26: 10859 | I26: RENATO DE SOUZA PEREIRA | J26: 9900 | K26: CARLOS ALVES DOS SANTOS | L26: CARLOS ALVES DOS SANTOS | M26: 43 | N26: APOIO E MANUTEÇÃO | O26: HA | P26: 496 | Q26: Santa Beatriz | R26: 24 | S26: 0 | T26: 5.94 | U26: 0 | V26: 0 | W26: 0 | X26: 0 | Y26: 0 | Z26: 0 | AA26: CONCLUIDO | AB26: Suporte | AC26: Carlos Alves dos Santos | AD26: Cilas Andrei da Silva Serrado | AE26: 46195.853 | AF26: ATIVIDADE JA RECEBIDA NA COMP 06 | AG26: =IF(B26=0,"",PROPER(TEXT(IF(DAY(B26)>20,EDATE(B26,1),B26),"MMMM-aa"))) -> Julho-26 | AH26: =_xlfn.XLOOKUP(AK26,'Base de Preços'!P$7:P$3001,'Base de Preços'!J$7:J$3001,"",0) -> 0 | AI26: =IF(AB26="Principal",AH26*T26,0) -> 0 | AJ26: =_xlfn.XLOOKUP(N26,Agrupamentos!C$3:C$496,Agrupamentos!D$3:D$496,"",0) -> APOIO E MANUTENÇÃO | AK26: =N26&D26&M26 -> APOIO E MANUTEÇÃOGN140043 | AL26: =CONCATENATE(A26,D26,F26,K26,N26,Q26,R26,AB26,T26,AG26,U26,V26,AE26,B26) -> 46495GN1400Operador de Trator de PneuCARLOS ALVES DOS SANTOSAPOIO E MANUTEÇÃOSanta Beatriz24Suporte5,94Julho-260046195,853391203746195 | AM26: =IFERROR(V26/W26,"") | AN26: =IFERROR(AM26*Z26,"") | AO26: =Z26*T26 -> 0 | AP26: =IFERROR(AO26-AN26,"")
A27: 46495 | B27: 46195 | C27: 1°- 07/2026 | D27: GN1400 | E27: Arauco - Silvicultura | F27: Operador de Trator de Pneu | G27: 8 | H27: 10859 | I27: RENATO DE SOUZA PEREIRA | J27: 9900 | K27: CARLOS ALVES DOS SANTOS | L27: CARLOS ALVES DOS SANTOS | M27: 43 | N27: APOIO E MANUTEÇÃO | O27: HA | P27: 496 | Q27: Santa Beatriz | R27: 22 | S27: 0 | T27: 26.16 | U27: 0 | V27: 0 | W27: 0 | X27: 0 | Y27: 0 | Z27: 0 | AA27: CONCLUIDO | AB27: Suporte | AC27: Carlos Alves dos Santos | AD27: Cilas Andrei da Silva Serrado | AE27: 46195.853 | AF27: ATIVIDADE JA RECEBIDA NA COMP 06 | AG27: =IF(B27=0,"",PROPER(TEXT(IF(DAY(B27)>20,EDATE(B27,1),B27),"MMMM-aa"))) -> Julho-26 | AH27: =_xlfn.XLOOKUP(AK27,'Base de Preços'!P$7:P$3001,'Base de Preços'!J$7:J$3001,"",0) -> 0 | AI27: =IF(AB27="Principal",AH27*T27,0) -> 0 | AJ27: =_xlfn.XLOOKUP(N27,Agrupamentos!C$3:C$496,Agrupamentos!D$3:D$496,"",0) -> APOIO E MANUTENÇÃO | AK27: =N27&D27&M27 -> APOIO E MANUTEÇÃOGN140043 | AL27: =CONCATENATE(A27,D27,F27,K27,N27,Q27,R27,AB27,T27,AG27,U27,V27,AE27,B27) -> 46495GN1400Operador de Trator de PneuCARLOS ALVES DOS SANTOSAPOIO E MANUTEÇÃOSanta Beatriz22Suporte26,16Julho-260046195,853391203746195 | AM27: =IFERROR(V27/W27,"") | AN27: =IFERROR(AM27*Z27,"") | AO27: =Z27*T27 -> 0 | AP27: =IFERROR(AO27-AN27,"")
A28: 46505 | B28: 46195 | C28: 1°- 07/2026 | D28: GN1400 | E28: Arauco - Silvicultura | F28: Trabalhador Florestal | G28: 8 | H28: 10859 | I28: RENATO DE SOUZA PEREIRA | J28: 10315 | K28: ANTONIO MARCIO PEREIRA DA SILVA | L28: ANTONIO MARCIO PEREIRA DA SILVA | M28: REF32 - 01 | N28: 1ª IRRIGAÇÃO DE REPLANTIO | O28: HA | P28: 410 | Q28: Canto do Pinhe | R28: 509 | S28: 40 | T28: 20.5 | U28: 0 | V28: 40 | W28: 2.69 | X28: 1.95 | Y28: 1.95 | Z28: 272.89 | AA28: CONCLUIDO | AB28: Principal | AC28: Antonio Marcio Pereira da Silva | AE28: 46195.966 | AG28: =IF(B28=0,"",PROPER(TEXT(IF(DAY(B28)>20,EDATE(B28,1),B28),"MMMM-aa"))) -> Julho-26 | AH28: =_xlfn.XLOOKUP(AK28,'Base de Preços'!P$7:P$3001,'Base de Preços'!J$7:J$3001,"",0) -> 551.6 | AI28: =IF(AB28="Principal",AH28*T28,0) -> 11307.8 | AJ28: =_xlfn.XLOOKUP(N28,Agrupamentos!C$3:C$496,Agrupamentos!D$3:D$496,"",0) -> IRRIGAÇÃO DE REPLANTIO | AK28: =N28&D28&M28 -> 1ª IRRIGAÇÃO DE REPLANTIOGN1400REF32 - 01 | AL28: =CONCATENATE(A28,D28,F28,K28,N28,Q28,R28,AB28,T28,AG28,U28,V28,AE28,B28) -> 46505GN1400Trabalhador FlorestalANTONIO MARCIO PEREIRA DA SILVA1ª IRRIGAÇÃO DE REPLANTIOCanto do Pinhe509Principal20,5Julho-2604046195,966134259346195 | AM28: =IFERROR(V28/W28,"") -> 14.869888 | AN28: =IFERROR(AM28*Z28,"") -> 4057.8439 | AO28: =Z28*T28 -> 5594.245 | AP28: =IFERROR(AO28-AN28,"") -> 1536.4011
A29: 46505 | B29: 46195 | C29: 1°- 07/2026 | D29: GN1400 | E29: Arauco - Silvicultura | F29: Motorista | G29: 8 | H29: 10859 | I29: RENATO DE SOUZA PEREIRA | J29: 10315 | K29: ANTONIO MARCIO PEREIRA DA SILVA | L29: ANTONIO MARCIO PEREIRA DA SILVA | M29: REF32 - 01 | N29: 1ª IRRIGAÇÃO DE REPLANTIO | O29: HA | P29: 410 | Q29: Canto do Pinhe | R29: 509 | S29: 9 | T29: 20.5 | U29: 0 | V29: 9 | W29: 0.18 | X29: 0.44 | Y29: 0.44 | Z29: 70.74 | AA29: CONCLUIDO | AB29: Suporte | AC29: Antonio Marcio Pereira da Silva | AE29: 46195.966 | AG29: =IF(B29=0,"",PROPER(TEXT(IF(DAY(B29)>20,EDATE(B29,1),B29),"MMMM-aa"))) -> Julho-26 | AH29: =_xlfn.XLOOKUP(AK29,'Base de Preços'!P$7:P$3001,'Base de Preços'!J$7:J$3001,"",0) -> 551.6 | AI29: =IF(AB29="Principal",AH29*T29,0) -> 0 | AJ29: =_xlfn.XLOOKUP(N29,Agrupamentos!C$3:C$496,Agrupamentos!D$3:D$496,"",0) -> IRRIGAÇÃO DE REPLANTIO | AK29: =N29&D29&M29 -> 1ª IRRIGAÇÃO DE REPLANTIOGN1400REF32 - 01 | AL29: =CONCATENATE(A29,D29,F29,K29,N29,Q29,R29,AB29,T29,AG29,U29,V29,AE29,B29) -> 46505GN1400MotoristaANTONIO MARCIO PEREIRA DA SILVA1ª IRRIGAÇÃO DE REPLANTIOCanto do Pinhe509Suporte20,5Julho-260946195,966134259346195 | AM29: =IFERROR(V29/W29,"") -> 50 | AN29: =IFERROR(AM29*Z29,"") -> 3537 | AO29: =Z29*T29 -> 1450.17 | AP29: =IFERROR(AO29-AN29,"") -> -2086.83
A30: 46505 | B30: 46195 | C30: 1°- 07/2026 | D30: GN1400 | E30: Arauco - Silvicultura | F30: Trabalhador Florestal | G30: 8 | H30: 10859 | I30: RENATO DE SOUZA PEREIRA | J30: 10315 | K30: ANTONIO MARCIO PEREIRA DA SILVA | L30: ANTONIO MARCIO PEREIRA DA SILVA | M30: REF29 | N30: REPLANTIO | O30: HA | P30: 410 | Q30: Canto do Pinhe | R30: 509 | S30: 32 | T30: 20.5 | U30: 0 | V30: 32 | W30: 3.18 | X30: 1.56 | Y30: 1.56 | Z30: 322.28 | AA30: CONCLUIDO | AB30: Principal | AC30: Antonio Marcio Pereira da Silva | AD30: Cilas Andrei da Silva Serrado | AE30: 46195.966 | AG30: =IF(B30=0,"",PROPER(TEXT(IF(DAY(B30)>20,EDATE(B30,1),B30),"MMMM-aa"))) -> Julho-26 | AH30: =_xlfn.XLOOKUP(AK30,'Base de Preços'!P$7:P$3001,'Base de Preços'!J$7:J$3001,"",0) -> 446.88 | AI30: =IF(AB30="Principal",AH30*T30,0) -> 9161.04 | AJ30: =_xlfn.XLOOKUP(N30,Agrupamentos!C$3:C$496,Agrupamentos!D$3:D$496,"",0) -> REPLANTIO | AK30: =N30&D30&M30 -> REPLANTIOGN1400REF29 | AL30: =CONCATENATE(A30,D30,F30,K30,N30,Q30,R30,AB30,T30,AG30,U30,V30,AE30,B30) -> 46505GN1400Trabalhador FlorestalANTONIO MARCIO PEREIRA DA SILVAREPLANTIOCanto do Pinhe509Principal20,5Julho-2603246195,966134259346195 | AM30: =IFERROR(V30/W30,"") -> 10.062893 | AN30: =IFERROR(AM30*Z30,"") -> 3243.0692 | AO30: =Z30*T30 -> 6606.74 | AP30: =IFERROR(AO30-AN30,"") -> 3363.6708
A31: 46505 | B31: 46195 | C31: 1°- 07/2026 | D31: GN1400 | E31: Arauco - Silvicultura | F31: Operador de Trator de Pneu | G31: 8 | H31: 10859 | I31: RENATO DE SOUZA PEREIRA | J31: 10315 | K31: ANTONIO MARCIO PEREIRA DA SILVA | L31: ANTONIO MARCIO PEREIRA DA SILVA | M31: REF32 - 01 | N31: 1ª IRRIGAÇÃO DE REPLANTIO | O31: HA | P31: 410 | Q31: Canto do Pinhe | R31: 509 | S31: 8 | T31: 20.5 | U31: 0 | V31: 8 | W31: 0.54 | X31: 0.39 | Y31: 0.39 | Z31: 207.97 | AA31: CONCLUIDO | AB31: Apoio | AC31: Antonio Marcio Pereira da Silva | AE31: 46195.966 | AG31: =IF(B31=0,"",PROPER(TEXT(IF(DAY(B31)>20,EDATE(B31,1),B31),"MMMM-aa"))) -> Julho-26 | AH31: =_xlfn.XLOOKUP(AK31,'Base de Preços'!P$7:P$3001,'Base de Preços'!J$7:J$3001,"",0) -> 551.6 | AI31: =IF(AB31="Principal",AH31*T31,0) -> 0 | AJ31: =_xlfn.XLOOKUP(N31,Agrupamentos!C$3:C$496,Agrupamentos!D$3:D$496,"",0) -> IRRIGAÇÃO DE REPLANTIO | AK31: =N31&D31&M31 -> 1ª IRRIGAÇÃO DE REPLANTIOGN1400REF32 - 01 | AL31: =CONCATENATE(A31,D31,F31,K31,N31,Q31,R31,AB31,T31,AG31,U31,V31,AE31,B31) -> 46505GN1400Operador de Trator de PneuANTONIO MARCIO PEREIRA DA SILVA1ª IRRIGAÇÃO DE REPLANTIOCanto do Pinhe509Apoio20,5Julho-260846195,966134259346195 | AM31: =IFERROR(V31/W31,"") -> 14.814815 | AN31: =IFERROR(AM31*Z31,"") -> 3081.037 | AO31: =Z31*T31 -> 4263.385 | AP31: =IFERROR(AO31-AN31,"") -> 1182.348
A32: 46505 | B32: 46195 | C32: 1°- 07/2026 | D32: GN1400 | E32: Arauco - Silvicultura | F32: Operador de Trator de Pneu | G32: 8 | H32: 10859 | I32: RENATO DE SOUZA PEREIRA | J32: 10315 | K32: ANTONIO MARCIO PEREIRA DA SILVA | L32: ANTONIO MARCIO PEREIRA DA SILVA | M32: REF29 | N32: REPLANTIO | O32: HA | P32: 410 | Q32: Canto do Pinhe | R32: 509 | S32: 8 | T32: 20.5 | U32: 0 | V32: 8 | W32: 0.4 | X32: 0.39 | Y32: 0.39 | Z32: 124.6 | AA32: CONCLUIDO | AB32: Apoio | AC32: Antonio Marcio Pereira da Silva | AE32: 46195.966 | AG32: =IF(B32=0,"",PROPER(TEXT(IF(DAY(B32)>20,EDATE(B32,1),B32),"MMMM-aa"))) -> Julho-26 | AH32: =_xlfn.XLOOKUP(AK32,'Base de Preços'!P$7:P$3001,'Base de Preços'!J$7:J$3001,"",0) -> 446.88 | AI32: =IF(AB32="Principal",AH32*T32,0) -> 0 | AJ32: =_xlfn.XLOOKUP(N32,Agrupamentos!C$3:C$496,Agrupamentos!D$3:D$496,"",0) -> REPLANTIO | AK32: =N32&D32&M32 -> REPLANTIOGN1400REF29 | AL32: =CONCATENATE(A32,D32,F32,K32,N32,Q32,R32,AB32,T32,AG32,U32,V32,AE32,B32) -> 46505GN1400Operador de Trator de PneuANTONIO MARCIO PEREIRA DA SILVAREPLANTIOCanto do Pinhe509Apoio20,5Julho-260846195,966134259346195 | AM32: =IFERROR(V32/W32,"") -> 20 | AN32: =IFERROR(AM32*Z32,"") -> 2492 | AO32: =Z32*T32 -> 2554.3 | AP32: =IFERROR(AO32-AN32,"") -> 62.3
A33: 46506 | B33: 46195 | C33: 1°- 07/2026 | D33: GN1400 | E33: Arauco - Silvicultura | F33: Trabalhador Florestal | G33: 8 | H33: 10859 | I33: RENATO DE SOUZA PEREIRA | J33: 10093 | K33: JONATHAN FONSECA DE OLIVEIRA | L33: JONATHAN FONSECA DE OLIVEIRA | M33: REF12 | N33: PLANTIO MANUAL 1.110 plantas/HA, mudas com tratamento (MAP e Cupinicida), mudas SEM TUBETE + Replantio | O33: HA | P33: 400 | Q33: Rosa Maria | R33: 378 | S33: 40 | T33: 11.93 | U33: 0 | V33: 40 | W33: 12.32 | X33: 3.35 | Y33: 3.35 | Z33: 1237.4 | AA33: CONCLUIDO | AB33: Principal | AC33: Jonathan Fonseca de Oliveira | AD33: Lucas Barbosa Ramos | AE33: 46195.99 | AG33: =IF(B33=0,"",PROPER(TEXT(IF(DAY(B33)>20,EDATE(B33,1),B33),"MMMM-aa"))) -> Julho-26 | AH33: =_xlfn.XLOOKUP(AK33,'Base de Preços'!P$7:P$3001,'Base de Preços'!J$7:J$3001,"",0) -> 1627.29 | AI33: =IF(AB33="Principal",AH33*T33,0) -> 19413.57 | AJ33: =_xlfn.XLOOKUP(N33,Agrupamentos!C$3:C$496,Agrupamentos!D$3:D$496,"",0) -> PLANTIO | AK33: =N33&D33&M33 -> PLANTIO MANUAL 1.110 plantas/HA, mudas com tratamento (MAP e Cupinicida), mudas SEM TUBETE + ReplantioGN1400REF12 | AL33: =CONCATENATE(A33,D33,F33,K33,N33,Q33,R33,AB33,T33,AG33,U33,V33,AE33,B33) -> 46506GN1400Trabalhador FlorestalJONATHAN FONSECA DE OLIVEIRAPLANTIO MANUAL 1.110 plantas/HA, mudas com tratamento (MAP e Cupinicida), mudas SEM TUBETE + ReplantioRosa Maria378Principal11,93Julho-2604046195,990324074146195 | AM33: =IFERROR(V33/W33,"") -> 3.2467532 | AN33: =IFERROR(AM33*Z33,"") -> 4017.5325 | AO33: =Z33*T33 -> 14762.182 | AP33: =IFERROR(AO33-AN33,"") -> 10744.65
A34: 46506 | B34: 46195 | C34: 1°- 07/2026 | D34: GN1400 | E34: Arauco - Silvicultura | F34: Trabalhador Florestal | G34: 8 | H34: 10859 | I34: RENATO DE SOUZA PEREIRA | J34: 10093 | K34: JONATHAN FONSECA DE OLIVEIRA | L34: JONATHAN FONSECA DE OLIVEIRA | M34: REF14 | N34: Irrigação de Plantio 4 a 5L/Planta+Polímero, tomadas d'água a 5 a 10KM da Operação, incluindo captação de água | O34: HA | P34: 400 | Q34: Rosa Maria | R34: 363 | S34: 40 | T34: 20 | U34: 0 | V34: 40 | W34: 4.58 | X34: 2 | Y34: 2 | Z34: 235.73 | AA34: CONCLUIDO | AB34: Principal | AC34: Jonathan Fonseca de Oliveira | AD34: Lucas Barbosa Ramos | AE34: 46195.99 | AG34: =IF(B34=0,"",PROPER(TEXT(IF(DAY(B34)>20,EDATE(B34,1),B34),"MMMM-aa"))) -> Julho-26 | AH34: =_xlfn.XLOOKUP(AK34,'Base de Preços'!P$7:P$3001,'Base de Preços'!J$7:J$3001,"",0) -> 1041.6 | AI34: =IF(AB34="Principal",AH34*T34,0) -> 20832 | AJ34: =_xlfn.XLOOKUP(N34,Agrupamentos!C$3:C$496,Agrupamentos!D$3:D$496,"",0) -> IRRIGAÇÃO DE PLANTIO | AK34: =N34&D34&M34 -> Irrigação de Plantio 4 a 5L/Planta+Polímero, tomadas d'água a 5 a 10KM da Operação, incluindo captação de águaGN1400REF14 | AL34: =CONCATENATE(A34,D34,F34,K34,N34,Q34,R34,AB34,T34,AG34,U34,V34,AE34,B34) -> 46506GN1400Trabalhador FlorestalJONATHAN FONSECA DE OLIVEIRAIrrigação de Plantio 4 a 5L/Planta+Polímero, tomadas d'água a 5 a 10KM da Operação, incluindo captação de águaRosa Maria363Principal20Julho-2604046195,990324074146195 | AM34: =IFERROR(V34/W34,"") -> 8.7336245 | AN34: =IFERROR(AM34*Z34,"") -> 2058.7773 | AO34: =Z34*T34 -> 4714.6 | AP34: =IFERROR(AO34-AN34,"") -> 2655.8227
A35: 46506 | B35: 46195 | C35: 1°- 07/2026 | D35: GN1400 | E35: Arauco - Silvicultura | F35: Trabalhador Florestal | G35: 8 | H35: 10859 | I35: RENATO DE SOUZA PEREIRA | J35: 10093 | K35: JONATHAN FONSECA DE OLIVEIRA | L35: JONATHAN FONSECA DE OLIVEIRA | M35: REF14 | N35: Irrigação de Plantio 4 a 5L/Planta+Polímero, tomadas d'água a 5 a 10KM da Operação, incluindo captação de água | O35: HA | P35: 400 | Q35: Rosa Maria | R35: 364 | S35: 40 | T35: 20 | U35: 0 | V35: 40 | W35: 4.58 | X35: 2 | Y35: 2 | Z35: 235.73 | AA35: CONCLUIDO | AB35: Principal | AC35: Jonathan Fonseca de Oliveira | AD35: Lucas Barbosa Ramos | AE35: 46195.99 | AG35: =IF(B35=0,"",PROPER(TEXT(IF(DAY(B35)>20,EDATE(B35,1),B35),"MMMM-aa"))) -> Julho-26 | AH35: =_xlfn.XLOOKUP(AK35,'Base de Preços'!P$7:P$3001,'Base de Preços'!J$7:J$3001,"",0) -> 1041.6 | AI35: =IF(AB35="Principal",AH35*T35,0) -> 20832 | AJ35: =_xlfn.XLOOKUP(N35,Agrupamentos!C$3:C$496,Agrupamentos!D$3:D$496,"",0) -> IRRIGAÇÃO DE PLANTIO | AK35: =N35&D35&M35 -> Irrigação de Plantio 4 a 5L/Planta+Polímero, tomadas d'água a 5 a 10KM da Operação, incluindo captação de águaGN1400REF14 | AL35: =CONCATENATE(A35,D35,F35,K35,N35,Q35,R35,AB35,T35,AG35,U35,V35,AE35,B35) -> 46506GN1400Trabalhador FlorestalJONATHAN FONSECA DE OLIVEIRAIrrigação de Plantio 4 a 5L/Planta+Polímero, tomadas d'água a 5 a 10KM da Operação, incluindo captação de águaRosa Maria364Principal20Julho-2604046195,990324074146195 | AM35: =IFERROR(V35/W35,"") -> 8.7336245 | AN35: =IFERROR(AM35*Z35,"") -> 2058.7773 | AO35: =Z35*T35 -> 4714.6 | AP35: =IFERROR(AO35-AN35,"") -> 2655.8227
A36: 46506 | B36: 46195 | C36: 1°- 07/2026 | D36: GN1400 | E36: Arauco - Silvicultura | F36: Operador de Trator de Pneu | G36: 8 | H36: 10859 | I36: RENATO DE SOUZA PEREIRA | J36: 10093 | K36: JONATHAN FONSECA DE OLIVEIRA | L36: JONATHAN FONSECA DE OLIVEIRA | M36: REF11 | N36: SUBSOLAGEM COM ADUBAÇÃO 350 a 400kg/ha, 40 a 50cm de profundidade, com bacia 3 a 4 litros, 2 turnos | O36: HA | P36: 400 | Q36: Rosa Maria | R36: 372 | S36: 4 | T36: 10 | U36: 16 | V36: 20 | W36: 1.59 | X36: 0.4 | Y36: 2 | Z36: 1104.72 | AA36: EM ANDAMENTO | AB36: Principal | AC36: Jonathan Fonseca de Oliveira | AD36: Cilas Andrei da Silva Serrado | AE36: 46195.99 | AG36: =IF(B36=0,"",PROPER(TEXT(IF(DAY(B36)>20,EDATE(B36,1),B36),"MMMM-aa"))) -> Julho-26 | AH36: =_xlfn.XLOOKUP(AK36,'Base de Preços'!P$7:P$3001,'Base de Preços'!J$7:J$3001,"",0) -> 1263.67 | AI36: =IF(AB36="Principal",AH36*T36,0) -> 12636.7 | AJ36: =_xlfn.XLOOKUP(N36,Agrupamentos!C$3:C$496,Agrupamentos!D$3:D$496,"",0) -> SUBSOSALGEM | AK36: =N36&D36&M36 -> SUBSOLAGEM COM ADUBAÇÃO 350 a 400kg/ha, 40 a 50cm de profundidade, com bacia 3 a 4 litros, 2 turnosGN1400REF11 | AL36: =CONCATENATE(A36,D36,F36,K36,N36,Q36,R36,AB36,T36,AG36,U36,V36,AE36,B36) -> 46506GN1400Operador de Trator de PneuJONATHAN FONSECA DE OLIVEIRASUBSOLAGEM COM ADUBAÇÃO 350 a 400kg/ha, 40 a 50cm de profundidade, com bacia 3 a 4 litros, 2 turnosRosa Maria372Principal10Julho-26162046195,990324074146195 | AM36: =IFERROR(V36/W36,"") -> 12.578616 | AN36: =IFERROR(AM36*Z36,"") -> 13895.849 | AO36: =Z36*T36 -> 11047.2 | AP36: =IFERROR(AO36-AN36,"") -> -2848.6491
A37: 46506 | B37: 46195 | C37: 1°- 07/2026 | D37: GN1400 | E37: Arauco - Silvicultura | F37: Trabalhador Florestal | G37: 8 | H37: 10859 | I37: RENATO DE SOUZA PEREIRA | J37: 10093 | K37: JONATHAN FONSECA DE OLIVEIRA | L37: JONATHAN FONSECA DE OLIVEIRA | M37: REF14 | N37: Irrigação de Plantio 4 a 5L/Planta+Polímero, tomadas d'água a 5 a 10KM da Operação, incluindo captação de água | O37: HA | P37: 400 | Q37: Rosa Maria | R37: 359 | S37: 12 | T37: 7.1 | U37: 0 | V37: 12 | W37: 4.58 | X37: 1.69 | Y37: 1.69 | Z37: 235.73 | AA37: EM ANDAMENTO | AB37: Principal | AC37: Jonathan Fonseca de Oliveira | AD37: Lucas Barbosa Ramos | AE37: 46196.355 | AG37: =IF(B37=0,"",PROPER(TEXT(IF(DAY(B37)>20,EDATE(B37,1),B37),"MMMM-aa"))) -> Julho-26 | AH37: =_xlfn.XLOOKUP(AK37,'Base de Preços'!P$7:P$3001,'Base de Preços'!J$7:J$3001,"",0) -> 1041.6 | AI37: =IF(AB37="Principal",AH37*T37,0) -> 7395.36 | AJ37: =_xlfn.XLOOKUP(N37,Agrupamentos!C$3:C$496,Agrupamentos!D$3:D$496,"",0) -> IRRIGAÇÃO DE PLANTIO | AK37: =N37&D37&M37 -> Irrigação de Plantio 4 a 5L/Planta+Polímero, tomadas d'água a 5 a 10KM da Operação, incluindo captação de águaGN1400REF14 | AL37: =CONCATENATE(A37,D37,F37,K37,N37,Q37,R37,AB37,T37,AG37,U37,V37,AE37,B37) -> 46506GN1400Trabalhador FlorestalJONATHAN FONSECA DE OLIVEIRAIrrigação de Plantio 4 a 5L/Planta+Polímero, tomadas d'água a 5 a 10KM da Operação, incluindo captação de águaRosa Maria359Principal7,1Julho-2601246196,355127314846195 | AM37: =IFERROR(V37/W37,"") -> 2.6200873 | AN37: =IFERROR(AM37*Z37,"") -> 617.63319 | AO37: =Z37*T37 -> 1673.683 | AP37: =IFERROR(AO37-AN37,"") -> 1056.0498
A38: 46506 | B38: 46195 | C38: 1°- 07/2026 | D38: GN1400 | E38: Arauco - Silvicultura | F38: Operador de Trator de Pneu | G38: 8 | H38: 10859 | I38: RENATO DE SOUZA PEREIRA | J38: 10093 | K38: JONATHAN FONSECA DE OLIVEIRA | L38: JONATHAN FONSECA DE OLIVEIRA | M38: REF14 | N38: Irrigação de Plantio 4 a 5L/Planta+Polímero, tomadas d'água a 5 a 10KM da Operação, incluindo captação de água | O38: HA | P38: 400 | Q38: Rosa Maria | R38: 363 | S38: 4 | T38: 20 | U38: 0 | V38: 4 | W38: 0.92 | X38: 0.2 | Y38: 0.2 | Z38: 582.53 | AA38: CONCLUIDO | AB38: Apoio | AC38: Jonathan Fonseca de Oliveira | AD38: Lucas Barbosa Ramos | AE38: 46195.99 | AG38: =IF(B38=0,"",PROPER(TEXT(IF(DAY(B38)>20,EDATE(B38,1),B38),"MMMM-aa"))) -> Julho-26 | AH38: =_xlfn.XLOOKUP(AK38,'Base de Preços'!P$7:P$3001,'Base de Preços'!J$7:J$3001,"",0) -> 1041.6 | AI38: =IF(AB38="Principal",AH38*T38,0) -> 0 | AJ38: =_xlfn.XLOOKUP(N38,Agrupamentos!C$3:C$496,Agrupamentos!D$3:D$496,"",0) -> IRRIGAÇÃO DE PLANTIO | AK38: =N38&D38&M38 -> Irrigação de Plantio 4 a 5L/Planta+Polímero, tomadas d'água a 5 a 10KM da Operação, incluindo captação de águaGN1400REF14 | AL38: =CONCATENATE(A38,D38,F38,K38,N38,Q38,R38,AB38,T38,AG38,U38,V38,AE38,B38) -> 46506GN1400Operador de Trator de PneuJONATHAN FONSECA DE OLIVEIRAIrrigação de Plantio 4 a 5L/Planta+Polímero, tomadas d'água a 5 a 10KM da Operação, incluindo captação de águaRosa Maria363Apoio20Julho-260446195,990324074146195 | AM38: =IFERROR(V38/W38,"") -> 4.3478261 | AN38: =IFERROR(AM38*Z38,"") -> 2532.7391 | AO38: =Z38*T38 -> 11650.6 | AP38: =IFERROR(AO38-AN38,"") -> 9117.8609
A39: 46506 | B39: 46195 | C39: 1°- 07/2026 | D39: GN1400 | E39: Arauco - Silvicultura | F39: Trabalhador Florestal | G39: 8 | H39: 10859 | I39: RENATO DE SOUZA PEREIRA | J39: 10093 | K39: JONATHAN FONSECA DE OLIVEIRA | L39: JONATHAN FONSECA DE OLIVEIRA | M39: REF12 | N39: PLANTIO MANUAL 1.110 plantas/HA, mudas com tratamento (MAP e Cupinicida), mudas SEM TUBETE + Replantio | O39: HA | P39: 400 | Q39: Rosa Maria | R39: 359 | S39: 16 | T39: 18.29 | U39: 0 | V39: 16 | W39: 12.32 | X39: 0.87 | Y39: 0.87 | Z39: 1237.4 | AA39: EM ANDAMENTO | AB39: Principal | AC39: Jonathan Fonseca de Oliveira | AD39: Lucas Barbosa Ramos | AE39: 46196.353 | AG39: =IF(B39=0,"",PROPER(TEXT(IF(DAY(B39)>20,EDATE(B39,1),B39),"MMMM-aa"))) -> Julho-26 | AH39: =_xlfn.XLOOKUP(AK39,'Base de Preços'!P$7:P$3001,'Base de Preços'!J$7:J$3001,"",0) -> 1627.29 | AI39: =IF(AB39="Principal",AH39*T39,0) -> 29763.134 | AJ39: =_xlfn.XLOOKUP(N39,Agrupamentos!C$3:C$496,Agrupamentos!D$3:D$496,"",0) -> PLANTIO | AK39: =N39&D39&M39 -> PLANTIO MANUAL 1.110 plantas/HA, mudas com tratamento (MAP e Cupinicida), mudas SEM TUBETE + ReplantioGN1400REF12 | AL39: =CONCATENATE(A39,D39,F39,K39,N39,Q39,R39,AB39,T39,AG39,U39,V39,AE39,B39) -> 46506GN1400Trabalhador FlorestalJONATHAN FONSECA DE OLIVEIRAPLANTIO MANUAL 1.110 plantas/HA, mudas com tratamento (MAP e Cupinicida), mudas SEM TUBETE + ReplantioRosa Maria359Principal18,29Julho-2601646196,35328703746195 | AM39: =IFERROR(V39/W39,"") -> 1.2987013 | AN39: =IFERROR(AM39*Z39,"") -> 1607.013 | AO39: =Z39*T39 -> 22632.046 | AP39: =IFERROR(AO39-AN39,"") -> 21025.033
A40: 46506 | B40: 46195 | C40: 1°- 07/2026 | D40: GN1400 | E40: Arauco - Silvicultura | F40: Trabalhador Florestal | G40: 8 | H40: 10859 | I40: RENATO DE SOUZA PEREIRA | J40: 10093 | K40: JONATHAN FONSECA DE OLIVEIRA | L40: JONATHAN FONSECA DE OLIVEIRA | M40: REF14 | N40: Irrigação de Plantio 4 a 5L/Planta+Polímero, tomadas d'água a 5 a 10KM da Operação, incluindo captação de água | O40: HA | P40: 400 | Q40: Rosa Maria | R40: 359A | S40: 12 | T40: 6.9 | U40: 0 | V40: 12 | W40: 4.58 | X40: 1.74 | Y40: 1.74 | Z40: 235.73 | AA40: EM ANDAMENTO | AB40: Principal | AC40: Jonathan Fonseca de Oliveira | AD40: Lucas Barbosa Ramos | AE40: 46196.355 | AG40: =IF(B40=0,"",PROPER(TEXT(IF(DAY(B40)>20,EDATE(B40,1),B40),"MMMM-aa"))) -> Julho-26 | AH40: =_xlfn.XLOOKUP(AK40,'Base de Preços'!P$7:P$3001,'Base de Preços'!J$7:J$3001,"",0) -> 1041.6 | AI40: =IF(AB40="Principal",AH40*T40,0) -> 7187.04 | AJ40: =_xlfn.XLOOKUP(N40,Agrupamentos!C$3:C$496,Agrupamentos!D$3:D$496,"",0) -> IRRIGAÇÃO DE PLANTIO | AK40: =N40&D40&M40 -> Irrigação de Plantio 4 a 5L/Planta+Polímero, tomadas d'água a 5 a 10KM da Operação, incluindo captação de águaGN1400REF14 | AL40: =CONCATENATE(A40,D40,F40,K40,N40,Q40,R40,AB40,T40,AG40,U40,V40,AE40,B40) -> 46506GN1400Trabalhador FlorestalJONATHAN FONSECA DE OLIVEIRAIrrigação de Plantio 4 a 5L/Planta+Polímero, tomadas d'água a 5 a 10KM da Operação, incluindo captação de águaRosa Maria359APrincipal6,9Julho-2601246196,354733796346195 | AM40: =IFERROR(V40/W40,"") -> 2.6200873 | AN40: =IFERROR(AM40*Z40,"") -> 617.63319 | AO40: =Z40*T40 -> 1626.537 | AP40: =IFERROR(AO40-AN40,"") -> 1008.9038
A41: 46506 | B41: 46195 | C41: 1°- 07/2026 | D41: GN1400 | E41: Arauco - Silvicultura | F41: Operador de Trator de Pneu | G41: 8 | H41: 10859 | I41: RENATO DE SOUZA PEREIRA | J41: 10093 | K41: JONATHAN FONSECA DE OLIVEIRA | L41: JONATHAN FONSECA DE OLIVEIRA | M41: REF12 | N41: PLANTIO MANUAL 1.110 plantas/HA, mudas com tratamento (MAP e Cupinicida), mudas SEM TUBETE + Replantio | O41: HA | P41: 400 | Q41: Rosa Maria | R41: 378 | S41: 8 | T41: 11.93 | U41: 0 | V41: 8 | W41: 1.23 | X41: 0.67 | Y41: 0.67 | Z41: 389.89 | AA41: CONCLUIDO | AB41: Suporte | AC41: Jonathan Fonseca de Oliveira | AE41: 46195.99 | AG41: =IF(B41=0,"",PROPER(TEXT(IF(DAY(B41)>20,EDATE(B41,1),B41),"MMMM-aa"))) -> Julho-26 | AH41: =_xlfn.XLOOKUP(AK41,'Base de Preços'!P$7:P$3001,'Base de Preços'!J$7:J$3001,"",0) -> 1627.29 | AI41: =IF(AB41="Principal",AH41*T41,0) -> 0 | AJ41: =_xlfn.XLOOKUP(N41,Agrupamentos!C$3:C$496,Agrupamentos!D$3:D$496,"",0) -> PLANTIO | AK41: =N41&D41&M41 -> PLANTIO MANUAL 1.110 plantas/HA, mudas com tratamento (MAP e Cupinicida), mudas SEM TUBETE + ReplantioGN1400REF12 | AL41: =CONCATENATE(A41,D41,F41,K41,N41,Q41,R41,AB41,T41,AG41,U41,V41,AE41,B41) -> 46506GN1400Operador de Trator de PneuJONATHAN FONSECA DE OLIVEIRAPLANTIO MANUAL 1.110 plantas/HA, mudas com tratamento (MAP e Cupinicida), mudas SEM TUBETE + ReplantioRosa Maria378Suporte11,93Julho-260846195,990324074146195 | AM41: =IFERROR(V41/W41,"") -> 6.504065 | AN41: =IFERROR(AM41*Z41,"") -> 2535.8699 | AO41: =Z41*T41 -> 4651.3877 | AP41: =IFERROR(AO41-AN41,"") -> 2115.5178
A42: 46506 | B42: 46195 | C42: 1°- 07/2026 | D42: GN1400 | E42: Arauco - Silvicultura | F42: Motorista | G42: 8 | H42: 10859 | I42: RENATO DE SOUZA PEREIRA | J42: 10093 | K42: JONATHAN FONSECA DE OLIVEIRA | L42: JONATHAN FONSECA DE OLIVEIRA | M42: 43 | N42: APOIO E MANUTEÇÃO | O42: HA | P42: 400 | Q42: Rosa Maria | R42: 363 | S42: 8 | T42: 0 | U42: 0 | V42: 8 | W42: 0 | X42: 0 | Y42: 0 | Z42: 0 | AA42: CONCLUIDO | AB42: Principal | AC42: Jonathan Fonseca de Oliveira | AE42: 46195.99 | AG42: =IF(B42=0,"",PROPER(TEXT(IF(DAY(B42)>20,EDATE(B42,1),B42),"MMMM-aa"))) -> Julho-26 | AH42: =_xlfn.XLOOKUP(AK42,'Base de Preços'!P$7:P$3001,'Base de Preços'!J$7:J$3001,"",0) -> 0 | AI42: =IF(AB42="Principal",AH42*T42,0) -> 0 | AJ42: =_xlfn.XLOOKUP(N42,Agrupamentos!C$3:C$496,Agrupamentos!D$3:D$496,"",0) -> APOIO E MANUTENÇÃO | AK42: =N42&D42&M42 -> APOIO E MANUTEÇÃOGN140043 | AL42: =CONCATENATE(A42,D42,F42,K42,N42,Q42,R42,AB42,T42,AG42,U42,V42,AE42,B42) -> 46506GN1400MotoristaJONATHAN FONSECA DE OLIVEIRAAPOIO E MANUTEÇÃORosa Maria363Principal0Julho-260846195,990324074146195 | AM42: =IFERROR(V42/W42,"") | AN42: =IFERROR(AM42*Z42,"") | AO42: =Z42*T42 -> 0 | AP42: =IFERROR(AO42-AN42,"")
...

Sheet Agrupamentos
C1: Agrupamentos
C2: Operação | D2: Agrupamento
C3: SERV ADUBACAO SOLIDA MANUAL AGRIC | D3: ADUBAÇÃO MANUAL
C4: ADUBAÇÃO MANUAL EM COVETA LATERAL | D4: ADUBAÇÃO MANUAL
C5: READUBAÇÃO MECANIZADA DE 18 MESES | D5: ADUBAÇÃO MEC
C6: ADUBAÇÃO MECANIZADA DE 12 MESES | D6: ADUBAÇÃO MEC
C7: SERV ADUBACAO SOLIDA MEC AGRIC | D7: ADUBAÇÃO MEC
C8: ADUBAÇÃO MECANIZADA DE 6 MESES | D8: ADUBAÇÃO MEC
C9: CAPINA QUÍMICA MECÂNICA NA ENTRELINHA CONCEIÇÃO + ADUBAÇÃO 6 MESES | D9: ADUBAÇÃO MEC/CONCEIÇÃO
C10: CAPINA QUÍMICA MECÂNICA NA ENTRELINHA CONCEIÇÃO + ADUBAÇÃO 12 MESES | D10: ADUBAÇÃO MEC/CONCEIÇÃO
C11: APOIO E MANUTEÇÃO | D11: APOIO E MANUTENÇÃO
C12: APOIO E MANUTEÇÃO 1410 | D12: APOIO E MANUTENÇÃO
C13: EQUIPE DE BRIGADINHA FLORESTAL | D13: BRIGADINHA MSFL
... C145: ADUBAÇÃO 6 MESES 250KG/HA, EM FILETE CONTÍNUO | D145: ADUBAÇÃO MEC
C2396: GRADAGEM NA ENTRE LINHA
C2397: CAPINA QUÍMICA MECÂNICA NA ENTRELINHA CONCEIÇÃO 6 MESES
C2398: ADUBAÇÃO MECANIZADA DE 6 MESES
C2399: CAMINHÃO PIPA – PREVENÇÃO A INCÊNDIO - ANO 01
C2400: CAPINA QUÍMICA MECÂNICA NA ENTRELINHA CONCEIÇÃO 6 MESES
C2401: CAPINA QUÍMICA MECÂNICA NA ENTRELINHA CONCEIÇÃO 6 MESES
C2402: CAPINA QUÍMICA MECÂNICA NA ENTRELINHA CONCEIÇÃO 6 MESES
C2403: CAPINA QUÍMICA MECÂNICA NA ENTRELINHA CONCEIÇÃO 6 MESES
C2404: CAPINA QUÍMICA MECÂNICA NA ENTRELINHA CONCEIÇÃO 6 MESES
C2405: CAPINA QUÍMICA MECÂNICA NA ENTRELINHA CONCEIÇÃO 6 MESES
C2406: CAPINA QUÍMICA MECÂNICA NA ENTRELINHA CONCEIÇÃO 6 MESES
C2407: CAPINA QUÍMICA MECÂNICA NA ENTRELINHA CONCEIÇÃO 6 MESES
... C3637: ADUBAÇÃO REPLANTIO

Sheet Base de Preços
C1: Relatório CDO vs BMS | L1: Emitido Por: Cilas Andrei da Silva Serrado
L3: Data da Emissão: 25/07/2026 às 15:36
G4: =SUBTOTAL(9,G7:G142) -> 0 | K4: =SUBTOTAL(9,K7:K142) -> 0
A6: Código | B6: Operação | C6: Cód. Projeto | D6: Projeto | E6: Talhão | F6: Tamanho do Talhão | G6: Realizado CDO | H6: Realizado BMS | I6: BMS menos CDO | J6: Preço | K6: Total em CDO | L6: Total em BMS | M6: Dif. BMS - CDO | N6: Observação (BMS) | O6: CR | P6: OPERAÇÃO + CR +COD
A7: 46028 | B7: 2º IRRIGAÇÃO DE REPLANTIO | J7: 492.5 | O7: GN1400 | P7: =B7&O7&A7 -> 2º IRRIGAÇÃO DE REPLANTIOGN140046028
A8: 46059 | B8: 3° IRRIGAÇÃO DE REPLANTIO | J8: 492.5 | O8: GN1400 | P8: =B8&O8&A8 -> 3° IRRIGAÇÃO DE REPLANTIOGN140046059
A9: 46087 | B9: 4ª IRRIGAÇÃO DE REPLANTIO | J9: 492.5 | O9: GN1400 | P9: =B9&O9&A9 -> 4ª IRRIGAÇÃO DE REPLANTIOGN140046087
A10: 7 | B10: REPLANTIO | J10: 399 | O10: GN1400 | P10: =B10&O10&A10 -> REPLANTIOGN14007
